Workbook
Name Break: Break!$A$1:$I$150
Name Efficiency: Efficiency!$A$1:$Q$150
Name OverAll: 'OverAll Performance'!$A$1:$J$150

Sheet Efficiency
A1: Employee | B1: Total Working Hours | C1: Work Efficiency | D1: Attended Calls | E1: Efficiency in Percentage | F1: Active With Cust. | G1: Active Time | H1: Other | I1: Not Working % | J1: Call Keeping | K1: Break During Calls | L1: Non Break % | M1: % Other Work | N1: Long Time | O1: Short Time Holds | P1: Long Call Holds | Q1: No Hold
A2: Mum_Abdul Hamid (1008512) | B2: 08:15:43 | C2: 04:57:59 | D2: 98 | E2: 0.69541035 | F2: 0.55697139 | G2: 0.57848906 | H2: 0.00013448543 | I2: 0.25683354 | J2: 0.022492687 | K2: 0 | L2: 0.13858723 | M2: 0.0034629997 | N2: 2 | O2: 3 | P2: 0 | Q2: 0
A3: Mum_Afzal Husain (1008513) | B3: 08:15:36 | C3: 04:58:34 | D3: 23 | E3: 0.70127226 | F3: 0.58027307 | G3: 0.58625908 | H3: 3.3629271e-05 | I3: 0.25373285 | J3: 0.01614205 | K3: 0 | L3: 0.14120931 | M3: 0.0026230831 | N3: 2 | O3: 1 | P3: 0 | Q3: 0
A4: Mum_Anamika Gupta (1008514) | B4: 08:16:57 | C4: 04:49:35 | D4: 28 | E4: 0.67767854 | F4: 0.51708757 | G4: 0.54036288 | H4: 0.019653218 | I4: 0.26454707 | J4: 0.022705168 | K4: 0 | L4: 0.14870711 | M4: 0.0040245498 | N4: 6 | O4: 3 | P4: 4 | Q4: 1
A5: Mum_Anikuttan (1008515) | B5: 08:09:56 | C5: 04:17:32 | D5: 29 | E5: 0.72067534 | F5: 0.47720778 | G5: 0.49802694 | H5: 6.8036468e-05 | I5: 0.18356239 | J5: 0.027554769 | K5: 0 | L5: 0.28378011 | M5: 0.0070077562 | N5: 1 | O5: 2 | P5: 0 | Q5: 0
A6: Mum_Anil Kumar (1008516) | B6: 07:20:41 | C6: 03:19:44 | D6: 93 | E6: 0.77990368 | F6: 0.43288832 | G6: 0.43496842 | H6: 0.00037820052 | I6: 0.11364926 | J6: 0.017888885 | K6: 0 | L6: 0.41972694 | M6: 0.013388298 | N6: 0 | O6: 4 | P6: 0 | Q6: 0
A7: Mum_Anita Dixit (1008517) | B7: 05:00:09 | C7: 03:41:19 | D7: 92 | E7: 0.7759598 | F7: 0.6549503 | G7: 0.65761564 | H7: 0.0085512799 | I7: 0.16269643 | J7: 0.071186629 | K7: 0 | L7: 0.090343717 | M7: 0.009606308 | N7: 2 | O7: 8 | P7: 2 | Q7: 0
A8: Mum_Anita Ghore (1008518) | B8: 08:16:38 | C8: 04:12:46 | D8: 26 | E8: 0.7543022 | F8: 0.49476475 | G8: 0.5007383 | H8: 0 | I8: 0.15054702 | J8: 0.0081213504 | K8: 0 | L8: 0.32559232 | M8: 0.015001007 | N8: 0 | O8: 0 | P8: 0 | Q8: 0
A9: Mum_Anjali Deoram (1008519) | B9: 09:16:31 | C9: 05:52:08 | D9: 90 | E9: 0.72351209 | F9: 0.55128627 | G9: 0.58183343 | H9: 0.008684975 | I9: 0.22793567 | J9: 0.042226947 | K9: 0 | L9: 0.13147255 | M9: 0.0078464257 | N9: 0 | O9: 8 | P9: 3 | Q9: 1
A10: Mum_Anjali Sahay (1008520) | B10: 08:13:18 | C10: 04:52:29 | D10: 89 | E10: 0.68246869 | F10: 0.55206433 | G10: 0.57530914 | H10: 0.0007095074 | I10: 0.26559227 | J10: 0.016893033 | K10: 0 | L10: 0.13511048 | M10: 0.0063855666 | N10: 4 | O10: 0 | P10: 0 | Q10: 0
A11: Mum_Annu Latika (1008521) | B11: 08:20:41 | C11: 04:58:07 | D11: 54 | E11: 0.69192681 | F11: 0.56868946 | G11: 0.58520023 | H11: 0.0001664392 | I11: 0.26120968 | J11: 0.010052928 | K11: 0 | L11: 0.13970906 | M11: 0.0036616624 | N11: 2 | O11: 0 | P11: 0 | Q11: 0
A12: Mum_Anoop Narayan (1008522) | B12: 08:10:35 | C12: 04:55:28 | D12: 87 | E12: 0.70101625 | F12: 0.56035332 | G12: 0.56901648 | H12: 0.010667573 | I12: 0.2498726 | J12: 0.022592152 | K12: 0 | L12: 0.14115848 | M12: 0.0066927128 | N12: 2 | O12: 3 | P12: 3 | Q12: 0
A13: Mum_Anoop Raj (1008523) | B13: 08:04:10 | C13: 03:47:42 | D13: 65 | E13: 0.71237877 | F13: 0.41552496 | G13: 0.42578313 | H13: 0 | I13: 0.14616179 | J13: 0.044509466 | K13: 0 | L13: 0.37445783 | M13: 0.0090877797 | N13: 0 | O13: 8 | P13: 0 | Q13: 0
... A94: Hyd_Raji Abraham (1008604) | B94: 08:10:41 | C94: 04:44:35 | D94: 51 | E94: 0.67540841 | F94: 0.54373153 | G94: 0.55762372 | H94: 3.3966238e-05 | I94: 0.27590775 | J94: 0.022315818 | K94: 0 | L94: 0.14157128 | M94: 0.0025474678 | N94: 2 | O94: 3 | P94: 0 | Q94: 0
A95: Hyd_Rajshree Dhabekar (1008605) | B95: 08:15:13 | C95: 0 | D95: 52 | G95: 0 | H95: 0 | I95: 0.00013462121 | J95: 0 | K95: 0 | L95: 0.99986538 | M95: 0 | N95: 0 | O95: 0 | P95: 0 | Q95: 0
A96: Hyd_Rakhi Jodhani (1008606) | B96: 08:02:52 | C96: 01:13:06 | D96: 53 | E96: 0.87790232 | F96: 0.14431175 | G96: 0.1489369 | H96: 0 | I96: 0.016360624 | J96: 0.002450642 | K96: 0 | L96: 0.82783377 | M96: 0.0044180588 | N96: 1 | O96: 0 | P96: 0 | Q96: 0
A97: Hyd_Ramji Prasad (1008607) | B97: 08:19:26 | C97: 04:53:04 | D97: 54 | E97: 0.68049536 | F97: 0.55259294 | G97: 0.56517386 | H97: 0.00053393846 | I97: 0.26326503 | J97: 0.021090569 | K97: 0 | L97: 0.14770073 | M97: 0.0022358673 | N97: 4 | O97: 4 | P97: 0 | Q97: 0
A98: Del_Rashid (1008608) | B98: 08:02:10 | C98: 01:36:08 | D98: 55 | E98: 0.70085055 | F98: 0.18938818 | G98: 0.19450398 | H98: 0.00051849291 | I98: 0.083961286 | J98: 0.0043553405 | K98: 0 | L98: 0.71596958 | M98: 0.00069132389 | N98: 0 | O98: 0 | P98: 0 | Q98: 0
A99: Del_Rashmi Gajbe (1008609) | B99: 08:20:42 | C99: 04:16:57 | D99: 56 | E99: 0.68072236 | F99: 0.47077425 | G99: 0.47776446 | H99: 0.0023966447 | I99: 0.2328074 | J99: 0.033020438 | K99: 0 | L99: 0.24958392 | M99: 0.0044271353 | N99: 0 | O99: 5 | P99: 1 | Q99: 1
A100: Del_Ravi Kumar (1008610) | B100: 08:00:44 | C100: 04:47:03 | D100: 57 | E100: 0.69796563 | F100: 0.53862155 | G100: 0.54503536 | H100: 0.0019761476 | I100: 0.25176813 | J100: 0.050097074 | K100: 0 | L100: 0.1481764 | M100: 0.0029468867 | N100: 0 | O100: 6 | P100: 0 | Q100: 2
A101: Del_Ravinder Kaur (1008611) | B101: 08:01:53 | C101: 04:38:57 | D101: 58 | E101: 0.6762151 | F101: 0.53294366 | G101: 0.54141736 | H101: 0.00072631688 | I101: 0.27454778 | J101: 0.036730882 | K101: 0 | L101: 0.14415661 | M101: 0.0024210563 | N101: 3 | O101: 8 | P101: 0 | Q101: 2
A102: Del_Rekha Agarwal (1008612) | B102: 05:53:52 | C102: 02:53:07 | D102: 59 | E102: 0.87051626 | F102: 0.41310286 | G102: 0.42214582 | H102: 0.01874529 | I102: 0.049500754 | J102: 0.048323286 | K102: 0 | L102: 0.45695177 | M102: 0.0043330821 | N102: 0 | O102: 6 | P102: 2 | Q102: 0
A103: Del_Rekha Gupta (1008613) | B103: 08:16:02 | C103: 04:22:52 | D103: 60 | E103: 0.68126647 | F103: 0.50483838 | G103: 0.51501915 | H103: 0.00013439957 | I103: 0.24420402 | J103: 0.014783953 | K103: 0 | L103: 0.22300249 | M103: 0.0028559909 | N103: 2 | O103: 1 | P103: 0 | Q103: 0
A104: Del_Rekha Jain (1008614) | B104: 08:15:42 | C104: 04:25:29 | D104: 61 | E104: 0.66398499 | F104: 0.52390559 | G104: 0.52800753 | H104: 0 | I104: 0.26605474 | J104: 0.0075650595 | K104: 0 | L104: 0.19558201 | M104: 0.0027906664 | N104: 5 | O104: 0 | P104: 0 | Q104: 0
A105: Del_Renu Pratap (1008615) | B105: 08:16:30 | C105: 02:30:29 | D105: 62 | E105: 0.79396764 | F105: 0.2544478 | G105: 0.27710641 | H105: 0 | I105: 0.075125881 | J105: 0.025981873 | K105: 0 | L105: 0.62017456 | M105: 0.001611279 | N105: 1 | O105: 4 | P105: 0 | Q105: 1
A106: Del_Ritu Bhatnagar (1008616) | B106: 08:01:48 | C106: 04:52:13 | D106: 63 | E106: 0.71324546 | F106: 0.55517504 | G106: 0.56316591 | H106: 0 | I106: 0.2393801 | J106: 0.043344403 | K106: 0 | L106: 0.152207 | M106: 0.0019025875 | N106: 3 | O106: 5 | P106: 0 | Q106: 1
A107: Del_Rohit Nishchal (1008617) | B107: 08:17:09 | D107: 64 | G107: 0 | H107: 0 | I107: 0.0003017198 | J107: 0 | K107: 0 | L107: 0.99969828 | M107: 0 | N107: 0 | O107: 0 | P107: 0 | Q107: 0
A108: Del_Roli Bhatnagar (1008618) | B108: 08:15:43 | C108: 04:08:30 | D108: 65 | E108: 0.67973558 | F108: 0.47712067 | G108: 0.47967589 | H108: 0.0010758834 | I108: 0.23333221 | J108: 0.020542649 | K108: 0 | L108: 0.26278452 | M108: 0.0025888444 | N108: 3 | O108: 3 | P108: 1 | Q108: 0
A109: Del_Roma Rastogi (1008619) | B109: 08:31:02 | C109: 05:35:38 | D109: 66 | E109: 0.73349117 | F109: 0.61917031 | G109: 0.6272585 | H109: 0.00088056878 | I109: 0.232568 | J109: 0.028634792 | K109: 0 | L109: 0.10524428 | M109: 0.0054138673 | N109: 4 | O109: 4 | P109: 0 | Q109: 1
A110: Del_Roohi Haider (1008620) | B110: 08:00:11 | C110: 04:52:11 | D110: 67 | E110: 0.71079306 | F110: 0.55305265 | G110: 0.56457603 | H110: 3.4708965e-05 | I110: 0.24383048 | J110: 0.043872132 | K110: 0 | L110: 0.14452813 | M110: 0.0031585158 | N110: 1 | O110: 7 | P110: 0 | Q110: 0
A111: Del_Sajid Naqvi (1008621) | B111: 08:15:48 | C111: 05:00:37 | D111: 68 | E111: 0.70349858 | F111: 0.56195374 | G111: 0.56595401 | H111: 0.00013446282 | I111: 0.25248756 | J111: 0.040237999 | K111: 0 | L111: 0.13849671 | M111: 0.0026892564 | N111: 3 | O111: 6 | P111: 0 | Q111: 0
A112: Del_Salim (1008622) | B112: 08:15:56 | C112: 04:37:42 | D112: 69 | E112: 0.73491531 | F112: 0.48780078 | G112: 0.50467133 | H112: 0.0077967469 | I112: 0.19612851 | J112: 0.047486221 | K112: 0 | L112: 0.2409262 | M112: 0.0029909934 | N112: 2 | O112: 6 | P112: 1 | Q112: 2
A113: Del_Sanjay Hire (1008623) | B113: 08:15:52 | C113: 05:00:14 | D113: 70 | E113: 0.70334218 | F113: 0.55414762 | G113: 0.56332347 | H113: 0.0011091691 | I113: 0.24589944 | J113: 0.041039258 | K113: 0 | L113: 0.14059559 | M113: 0.0080330734 | N113: 3 | O113: 7 | P113: 1 | Q113: 0
A114: Del_Sanjiv Subherwal (1008624) | B114: 08:02:17 | C114: 05:06:07 | D114: 71 | E114: 0.74219097 | F114: 0.58651553 | G114: 0.59615717 | H114: 6.9115665e-05 | I114: 0.217507 | J114: 0.038497425 | K114: 0 | L114: 0.14566126 | M114: 0.0021080278 | N114: 2 | O114: 6 | P114: 0 | Q114: 0
A115: Del_Sanju Ramdas (1008625) | B115: 08:15:58 | C115: 05:19:44 | D115: 72 | E115: 0.75727312 | F115: 0.58165871 | G115: 0.59157201 | H115: 0.00030243968 | I115: 0.20360911 | J115: 0.052792526 | K115: 0 | L115: 0.14906916 | M115: 0.0026547483 | N115: 3 | O115: 9 | P115: 0 | Q115: 4
A116: Del_Santosh Kumar (1008626) | B116: 08:00:32 | C116: 05:03:10 | D116: 73 | E116: 0.73745236 | F116: 0.59073252 | G116: 0.60477941 | H116: 0.00013873474 | I116: 0.21885405 | J116: 0.02597808 | K116: 0 | L116: 0.14525527 | M116: 0.0049944506 | N116: 2 | O116: 4 | P116: 0 | Q116: 0
A117: Del_Santosh Kumar (1008627) | B117: 08:17:04 | C117: 05:09:57 | D117: 74 | E117: 0.72636019 | F117: 0.58640692 | G117: 0.58717811 | H117: 0.0015088519 | I117: 0.23226261 | J117: 0.034871245 | K117: 0 | L117: 0.14277092 | M117: 0.0014082618 | N117: 4 | O117: 4 | P117: 1 | Q117: 0
A118: Del_Santosh Kumar (1008628) | B118: 08:02:59 | C118: 04:44:19 | D118: 75 | E118: 0.68830697 | F118: 0.5465337 | G118: 0.54957038 | H118: 0.00048310846 | I118: 0.26067152 | J118: 0.038614169 | K118: 0 | L118: 0.14910797 | M118: 0.0015528486 | N118: 2 | O118: 6 | P118: 0 | Q118: 2
A119: Del_Sapna Sharma (1008629) | B119: 08:04:14 | C119: 04:33:29 | D119: 76 | E119: 0.69671365 | F119: 0.53238797 | G119: 0.5558615 | H119: 6.8837337e-05 | I119: 0.24199766 | J119: 0.0088455979 | K119: 0 | L119: 0.19126454 | M119: 0.0019618641 | N119: 1 | O119: 0 | P119: 0 | Q119: 0
... A150: Del_Tasneem Khan (1008660) | B150: 08:33:55 | C150: 04:38:49 | D150: 107 | E150: 0.73796815 | F150: 0.49813524 | G150: 0.50796173 | H150: 0.0024647316 | I150: 0.18394681 | J150: 0.032106373 | K150: 0 | L150: 0.26628831 | M150: 0.0072320415 | N150: 4 | O150: 5 | P150: 0 | Q150: 0

Sheet Break
A1: Employee | B1: Lunch | C1: Normal Break | D1: Feedback | E1: Training | F1: Meeting | G1: Unwanted Break | H1: Other Work | I1: Total Break Taken
A2: Mum_Abdul Hamid (1008512) | B2: 00:36:49 | C2: 00:30:24 | D2: 00:00:00 | E2: 00:00:00 | F2: 00:00:00 | G2: 00:00:00 | H2: 00:00:00 | I2: 01:08:42
A3: Mum_Afzal Husain (1008513) | B3: 00:39:56 | C3: 00:29:55 | D3: 00:00:00 | E3: 00:00:00 | F3: 00:00:00 | G3: 00:00:00 | H3: 00:00:00 | I3: 01:09:59
A4: Mum_Anamika Gupta (1008514) | B4: 00:39:49 | C4: 00:29:49 | D4: 00:00:00 | E4: 00:00:00 | F4: 00:00:00 | G4: 00:04:09 | H4: 00:00:00 | I4: 01:13:54
A5: Mum_Anikuttan (1008515) | B5: 00:39:17 | C5: 00:22:20 | D5: 01:10:58 | E5: 00:00:00 | F5: 00:00:00 | G5: 00:00:00 | H5: 00:00:00 | I5: 02:19:02
A6: Mum_Anil Kumar (1008516) | B6: 00:00:00 | C6: 00:29:44 | D6: 00:00:00 | E6: 00:00:00 | F6: 00:29:31 | G6: 00:00:00 | H6: 02:05:20 | I6: 03:04:58
A7: Mum_Anita Dixit (1008517) | B7: 00:00:00 | C7: 00:14:56 | D7: 00:00:00 | E7: 00:00:00 | F7: 00:00:00 | G7: 00:10:12 | H7: 00:00:00 | I7: 00:27:07
A8: Mum_Anita Ghore (1008518) | B8: 00:39:59 | C8: 00:29:58 | D8: 00:00:00 | E8: 00:00:00 | F8: 00:00:00 | G8: 00:00:00 | H8: 01:31:35 | I8: 02:41:42
A9: Mum_Anjali Deoram (1008519) | B9: 00:40:23 | C9: 00:29:26 | D9: 00:00:00 | E9: 00:00:00 | F9: 00:00:00 | G9: 00:00:00 | H9: 00:00:00 | I9: 01:13:10
A10: Mum_Anjali Sahay (1008520) | B10: 00:39:55 | C10: 00:24:49 | D10: 00:00:00 | E10: 00:00:00 | F10: 00:00:00 | G10: 00:00:00 | H10: 00:00:00 | I10: 01:06:39
A11: Mum_Annu Latika (1008521) | B11: 00:39:51 | C11: 00:29:59 | D11: 00:00:00 | E11: 00:00:00 | F11: 00:00:00 | G11: 00:00:00 | H11: 00:00:00 | I11: 01:09:57
A12: Mum_Anoop Narayan (1008522) | B12: 00:39:41 | C12: 00:29:25 | D12: 00:00:00 | E12: 00:00:00 | F12: 00:00:00 | G12: 00:00:00 | H12: 00:00:00 | I12: 01:09:15
... A150: Del_Tasneem Khan (1008660) | B150: 00:40:06 | C150: 00:29:10 | D150: 01:06:50 | E150: 00:00:00 | F150: 00:00:00 | G150: 00:00:00 | H150: 00:00:00 | I150: 02:16:51

Sheet OverAll Performance
A1: Employee | B1: Attended Calls | C1: Transferred calls | D1: Call Conferenced | E1: Call Redirected | F1: Hold Calls | G1: % of Calls onHold | H1: Average Duration of Calls | I1: Avg. In Focus Hold Calls | J1: Calls Unattend Time'
A2: Mum_Abdul Hamid (1008512) | B2: 98 | C2: 0 | D2: 0 | E2: 0 | F2: 0.10294118 | G2: 0 | H2: 00:04:13 | I2: 00:00:01 | J2: 00:00:09
A3: Mum_Afzal Husain (1008513) | B3: 23 | C3: 0 | D3: 0 | E3: 0 | F3: 0.10294118 | G3: 0 | H3: 00:04:13 | I3: 00:00:01 | J3: 00:00:09
A4: Mum_Anamika Gupta (1008514) | B4: 28 | C4: 0.014705882 | D4: 0 | E4: 0 | F4: 0.073529412 | G4: 0 | H4: 00:04:10 | I4: 00:00:00 | J4: 00:00:07
A5: Mum_Anikuttan (1008515) | B5: 29 | C5: 0.014705882 | D5: 0 | E5: 0 | F5: 0.073529412 | G5: 0 | H5: 00:04:10 | I5: 00:00:00 | J5: 00:00:07
A6: Mum_Anil Kumar (1008516) | B6: 93 | C6: 0.083333333 | D6: 0 | E6: 0 | F6: 0.16666667 | G6: 0.1 | H6: 00:04:25 | I6: 00:00:59 | J6: 00:00:11
A7: Mum_Anita Dixit (1008517) | B7: 92 | C7: 0.083333333 | D7: 0 | E7: 0 | F7: 0.16666667 | G7: 0.1 | H7: 00:04:25 | I7: 00:00:59 | J7: 00:00:11
A8: Mum_Anita Ghore (1008518) | B8: 26 | C8: 0.054545455 | D8: 0 | E8: 0.017857143 | F8: 0.10909091 | G8: 0 | H8: 00:04:26 | I8: 00:00:00 | J8: 00:00:14
A9: Mum_Anjali Deoram (1008519) | B9: 90 | C9: 0.054545455 | D9: 0 | E9: 0.017857143 | F9: 0.10909091 | G9: 0 | H9: 00:04:26 | I9: 00:00:00 | J9: 00:00:14
A10: Mum_Anjali Sahay (1008520) | B10: 89 | C10: 0 | D10: 0 | E10: 0 | F10: 0.068181818 | G10: 0 | H10: 00:03:26 | I10: 00:00:03 | J10: 00:00:10
A11: Mum_Annu Latika (1008521) | B11: 54 | C11: 0 | D11: 0 | E11: 0 | F11: 0.068181818 | G11: 0 | H11: 00:03:26 | I11: 00:00:03 | J11: 00:00:10
A12: Mum_Anoop Narayan (1008522) | B12: 87 | C12: 0 | D12: 0 | E12: 0 | F12: 0.065217391 | G12: 0 | H12: 00:03:54 | I12: 00:00:51 | J12: 00:00:27
A13: Mum_Anoop Raj (1008523) | B13: 65 | C13: 0 | D13: 0 | E13: 0 | F13: 0.065217391 | G13: 0 | H13: 00:03:54 | I13: 00:00:51 | J13: 00:00:27
... A51: Hyd_Leena George (1008561) | B51: 48 | C51: 0.043478261 | D51: 0 | E51: 0.054794521 | F51: 0.072463768 | G51: 0.2 | H51: 00:03:57 | I51: 00:01:29 | J51: 00:00:19
A52: Hyd_Lilly Lucy (1008562) | B52: 47 | C52: 0 | D52: 0 | E52: 0 | F52: 0 | G52: 0 | H52: 00:04:47 | J52: 00:00:08
A53: Hyd_Mangal Singh (1008563) | B53: 46 | C53: 0 | D53: 0 | E53: 0 | F53: 0 | G53: 0 | H53: 00:04:47 | J53: 00:00:08
A54: Hyd_Manisha Shrivastava (1008564) | B54: 45 | C54: 0.11111111 | D54: 0 | E54: 0 | F54: 0.22222222 | G54: 0 | H54: 00:03:54 | I54: 00:00:23 | J54: 00:00:04
A55: Hyd_Manjusha Sinha (1008565) | B55: 44 | C55: 0.11111111 | D55: 0 | E55: 0 | F55: 0.22222222 | G55: 0 | H55: 00:03:54 | I55: 00:00:23 | J55: 00:00:04
A56: Hyd_ManjuTiwari Lab (1008566) | B56: 43 | C56: 0.14492754 | D56: 0 | E56: 0 | F56: 0.20289855 | G56: 0.071428571 | H56: 00:03:50 | I56: 00:00:17 | J56: 00:00:29
A57: Hyd_Manoj Kumar (1008567) | B57: 42 | C57: 0.14492754 | D57: 0 | E57: 0 | F57: 0.20289855 | G57: 0.071428571 | H57: 00:03:50 | I57: 00:00:17 | J57: 00:00:29
A58: Hyd_Manoj Kumar (1008568) | B58: 41 | C58: 0.06779661 | D58: 0 | E58: 0 | F58: 0.11864407 | G58: 0 | H58: 00:03:47 | I58: 00:00:18 | J58: 00:00:27
A59: Hyd_Masroor Adil (1008569) | B59: 40 | C59: 0.06779661 | D59: 0 | E59: 0 | F59: 0.11864407 | G59: 0 | H59: 00:03:47 | I59: 00:00:18 | J59: 00:00:27
A60: Hyd_Meena Zinjare (1008570) | B60: 39 | C60: 0.026315789 | D60: 0 | E60: 0.049382716 | F60: 0.078947368 | G60: 0.16666667 | H60: 00:03:07 | I60: 00:01:21 | J60: 00:00:19
A61: Hyd_Mehnaz Khan (1008571) | B61: 38 | C61: 0.026315789 | D61: 0 | E61: 0.049382716 | F61: 0.078947368 | G61: 0.16666667 | H61: 00:03:07 | I61: 00:01:21 | J61: 00:00:19
A62: Hyd_Mercy Thampi (1008572) | B62: 37 | C62: 0.037974684 | D62: 0 | E62: 0 | F62: 0.075949367 | G62: 0.16666667 | H62: 00:03:28 | I62: 00:00:17 | J62: 00:00:23
A63: Hyd_Miny Mole (1008573) | B63: 36 | C63: 0.037974684 | D63: 0 | E63: 0 | F63: 0.075949367 | G63: 0.16666667 | H63: 00:03:28 | I63: 00:00:17 | J63: 00:00:23
A64: Hyd_Mohd Rafi (1008574) | B64: 35 | C64: 0.087719298 | D64: 0 | E64: 0 | F64: 0.10526316 | G64: 0 | H64: 00:04:29 | I64: 00:00:17 | J64: 00:00:50
A65: Hyd_Mubeen Khan (1008575) | B65: 34 | C65: 0.087719298 | D65: 0 | E65: 0 | F65: 0.10526316 | G65: 0 | H65: 00:04:29 | I65: 00:00:17 | J65: 00:00:50
... A109: Del_Roma Rastogi (1008619) | B109: 66 | C109: 0.048387097 | D109: 0 | E109: 0 | F109: 0.096774194 | G109: 0 | H109: 00:04:25 | I109: 00:00:00 | J109: 00:00:29
A110: Del_Roohi Haider (1008620) | B110: 67 | C110: 0 | D110: 0 | E110: 0 | F110: 0 | G110: 0 | H110: 00:03:32 | J110: 00:00:19
A111: Del_Sajid Naqvi (1008621) | B111: 68 | C111: 0 | D111: 0 | E111: 0 | F111: 0 | G111: 0 | H111: 00:03:32 | J111: 00:00:19
A112: Del_Salim (1008622) | B112: 69 | C112: 0.052631579 | D112: 0 | E112: 0 | F112: 0.14473684 | G112: 0.63636364 | H112: 00:03:27 | I112: 00:00:00 | J112: 00:00:05
A113: Del_Sanjay Hire (1008623) | B113: 70 | C113: 0.052631579 | D113: 0 | E113: 0 | F113: 0.14473684 | G113: 0.63636364 | H113: 00:03:27 | I113: 00:00:00 | J113: 00:00:05
A114: Del_Sanjiv Subherwal (1008624) | B114: 71 | C114: 0.027777778 | D114: 0 | E114: 0.01369863 | F114: 0.041666667 | G114: 0 | H114: 00:03:31 | I114: 00:00:08 | J114: 00:00:11
A115: Del_Sanju Ramdas (1008625) | B115: 72 | C115: 0.027777778 | D115: 0 | E115: 0.01369863 | F115: 0.041666667 | G115: 0 | H115: 00:03:31 | I115: 00:00:08 | J115: 00:00:11
A116: Del_Santosh Kumar (1008626) | B116: 73 | C116: 0.030769231 | D116: 0 | E116: 0.029850746 | F116: 0.076923077 | G116: 0.2 | H116: 00:04:03 | I116: 00:00:01 | J116: 00:00:10
A117: Del_Santosh Kumar (1008627) | B117: 74 | C117: 0.030769231 | D117: 0 | E117: 0.029850746 | F117: 0.076923077 | G117: 0.2 | H117: 00:04:03 | I117: 00:00:01 | J117: 00:00:10
A118: Del_Santosh Kumar (1008628) | B118: 75 | C118: 0.13636364 | D118: 0 | E118: 0 | F118: 0.20454545 | G118: 0 | H118: 00:03:58 | I118: 00:01:03 | J118: 00:00:07
A119: Del_Sapna Sharma (1008629) | B119: 76 | C119: 0.13636364 | D119: 0 | E119: 0 | F119: 0.20454545 | G119: 0 | H119: 00:03:58 | I119: 00:01:03 | J119: 00:00:07
A120: Del_Saroj Parita (1008630) | B120: 77 | C120: 0.016393443 | D120: 0 | E120: 0 | F120: 0.081967213 | G120: 0 | H120: 00:03:55 | I120: 00:00:03 | J120: 00:00:06
...

Sheet Summary
A1: =[1]Break!A1 -> Employee | B1: Emp Name | C1: Total Number of woking hours | D1: Work Efficiency | E1: Total Break Taken | F1: Attended Calls | G1: Active With Cust.
A2: =Break!A2 -> Mum_Abdul Hamid (1008512) | B2: =MID(A2,FIND("_",A2,1)+1,FIND("(",A2,1)-FIND("_",A2,1)-1) -> Abdul Hamid | C2: =VLOOKUP($A2,Efficiency,2,0) -> 08:15:43 | D2: =VLOOKUP(A2,Efficiency,3,0) -> 04:57:59 | E2: =VLOOKUP(A2,Break,9,0) -> 01:08:42 | F2: =VLOOKUP(A2,OverAll,2,0) -> 98 | G2: =VLOOKUP(A2,Efficiency,6,0) -> 0.55697139
A3: =Break!A3 -> Mum_Afzal Husain (1008513) | B3: =MID(A3,FIND("_",A3,1)+1,FIND("(",A3,1)-FIND("_",A3,1)-1) -> Afzal Husain | C3: =VLOOKUP($A3,Efficiency,2,0) -> 08:15:36 | D3: =VLOOKUP(A3,Efficiency,3,0) -> 04:58:34 | E3: =VLOOKUP(A3,Break,9,0) -> 01:09:59 | F3: =VLOOKUP(A3,OverAll,2,0) -> 23 | G3: =VLOOKUP(A3,Efficiency,6,0) -> 0.58027307
A4: =Break!A4 -> Mum_Anamika Gupta (1008514) | B4: =MID(A4,FIND("_",A4,1)+1,FIND("(",A4,1)-FIND("_",A4,1)-1) -> Anamika Gupta | C4: =VLOOKUP($A4,Efficiency,2,0) -> 08:16:57 | D4: =VLOOKUP(A4,Efficiency,3,0) -> 04:49:35 | E4: =VLOOKUP(A4,Break,9,0) -> 01:13:54 | F4: =VLOOKUP(A4,OverAll,2,0) -> 28 | G4: =VLOOKUP(A4,Efficiency,6,0) -> 0.51708757
A5: =Break!A5 -> Mum_Anikuttan (1008515) | B5: =MID(A5,FIND("_",A5,1)+1,FIND("(",A5,1)-FIND("_",A5,1)-1) -> Anikuttan | C5: =VLOOKUP($A5,Efficiency,2,0) -> 08:09:56 | D5: =VLOOKUP(A5,Efficiency,3,0) -> 04:17:32 | E5: =VLOOKUP(A5,Break,9,0) -> 02:19:02 | F5: =VLOOKUP(A5,OverAll,2,0) -> 29 | G5: =VLOOKUP(A5,Efficiency,6,0) -> 0.47720778
A6: =Break!A6 -> Mum_Anil Kumar (1008516) | B6: =MID(A6,FIND("_",A6,1)+1,FIND("(",A6,1)-FIND("_",A6,1)-1) -> Anil Kumar | C6: =VLOOKUP($A6,Efficiency,2,0) -> 07:20:41 | D6: =VLOOKUP(A6,Efficiency,3,0) -> 03:19:44 | E6: =VLOOKUP(A6,Break,9,0) -> 03:04:58 | F6: =VLOOKUP(A6,OverAll,2,0) -> 93 | G6: =VLOOKUP(A6,Efficiency,6,0) -> 0.43288832
A7: =Break!A7 -> Mum_Anita Dixit (1008517) | B7: =MID(A7,FIND("_",A7,1)+1,FIND("(",A7,1)-FIND("_",A7,1)-1) -> Anita Dixit | C7: =VLOOKUP($A7,Efficiency,2,0) -> 05:00:09 | D7: =VLOOKUP(A7,Efficiency,3,0) -> 03:41:19 | E7: =VLOOKUP(A7,Break,9,0) -> 00:27:07 | F7: =VLOOKUP(A7,OverAll,2,0) -> 92 | G7: =VLOOKUP(A7,Efficiency,6,0) -> 0.6549503
A8: =Break!A8 -> Mum_Anita Ghore (1008518) | B8: =MID(A8,FIND("_",A8,1)+1,FIND("(",A8,1)-FIND("_",A8,1)-1) -> Anita Ghore | C8: =VLOOKUP($A8,Efficiency,2,0) -> 08:16:38 | D8: =VLOOKUP(A8,Efficiency,3,0) -> 04:12:46 | E8: =VLOOKUP(A8,Break,9,0) -> 02:41:42 | F8: =VLOOKUP(A8,OverAll,2,0) -> 26 | G8: =VLOOKUP(A8,Efficiency,6,0) -> 0.49476475
A9: =Break!A9 -> Mum_Anjali Deoram (1008519) | B9: =MID(A9,FIND("_",A9,1)+1,FIND("(",A9,1)-FIND("_",A9,1)-1) -> Anjali Deoram | C9: =VLOOKUP($A9,Efficiency,2,0) -> 09:16:31 | D9: =VLOOKUP(A9,Efficiency,3,0) -> 05:52:08 | E9: =VLOOKUP(A9,Break,9,0) -> 01:13:10 | F9: =VLOOKUP(A9,OverAll,2,0) -> 90 | G9: =VLOOKUP(A9,Efficiency,6,0) -> 0.55128627
A10: =Break!A10 -> Mum_Anjali Sahay (1008520) | B10: =MID(A10,FIND("_",A10,1)+1,FIND("(",A10,1)-FIND("_",A10,1)-1) -> Anjali Sahay | C10: =VLOOKUP($A10,Efficiency,2,0) -> 08:13:18 | D10: =VLOOKUP(A10,Efficiency,3,0) -> 04:52:29 | E10: =VLOOKUP(A10,Break,9,0) -> 01:06:39 | F10: =VLOOKUP(A10,OverAll,2,0) -> 89 | G10: =VLOOKUP(A10,Efficiency,6,0) -> 0.55206433
A11: =Break!A11 -> Mum_Annu Latika (1008521) | B11: =MID(A11,FIND("_",A11,1)+1,FIND("(",A11,1)-FIND("_",A11,1)-1) -> Annu Latika | C11: =VLOOKUP($A11,Efficiency,2,0) -> 08:20:41 | D11: =VLOOKUP(A11,Efficiency,3,0) -> 04:58:07 | E11: =VLOOKUP(A11,Break,9,0) -> 01:09:57 | F11: =VLOOKUP(A11,OverAll,2,0) -> 54 | G11: =VLOOKUP(A11,Efficiency,6,0) -> 0.56868946
A12: =Break!A12 -> Mum_Anoop Narayan (1008522) | B12: =MID(A12,FIND("_",A12,1)+1,FIND("(",A12,1)-FIND("_",A12,1)-1) -> Anoop Narayan | C12: =VLOOKUP($A12,Efficiency,2,0) -> 08:10:35 | D12: =VLOOKUP(A12,Efficiency,3,0) -> 04:55:28 | E12: =VLOOKUP(A12,Break,9,0) -> 01:09:15 | F12: =VLOOKUP(A12,OverAll,2,0) -> 87 | G12: =VLOOKUP(A12,Efficiency,6,0) -> 0.56035332
A13: =Break!A13 -> Mum_Anoop Raj (1008523) | B13: =MID(A13,FIND("_",A13,1)+1,FIND("(",A13,1)-FIND("_",A13,1)-1) -> Anoop Raj | C13: =VLOOKUP($A13,Efficiency,2,0) -> 08:04:10 | D13: =VLOOKUP(A13,Efficiency,3,0) -> 03:47:42 | E13: =VLOOKUP(A13,Break,9,0) -> 03:01:18 | F13: =VLOOKUP(A13,OverAll,2,0) -> 65 | G13: =VLOOKUP(A13,Efficiency,6,0) -> 0.41552496
... A150: =Break!A150 -> Del_Tasneem Khan (1008660) | B150: =MID(A150,FIND("_",A150,1)+1,FIND("(",A150,1)-FIND("_",A150,1)-1) -> Tasneem Khan | C150: =VLOOKUP($A150,Efficiency,2,0) -> 08:33:55 | D150: =VLOOKUP(A150,Efficiency,3,0) -> 04:38:49 | E150: =VLOOKUP(A150,Break,9,0) -> 02:16:51 | F150: =VLOOKUP(A150,OverAll,2,0) -> 107 | G150: =VLOOKUP(A150,Efficiency,6,0) -> 0.49813524
